<sdf version='1.6'>
  <world name='default'>
    <light name='sun' type='directional'>
      <cast_shadows>1</cast_shadows>
      <pose frame=''>0 0 10 0 -0 0</pose>
      <diffuse>0.8 0.8 0.8 1</diffuse>
      <specular>0.1 0.1 0.1 1</specular>
      <attenuation>
        <range>1000</range>
        <constant>0.9</constant>
        <linear>0.01</linear>
        <quadratic>0.001</quadratic>
      </attenuation>
      <direction>-0.5 0.5 -1</direction>
    </light>
    <model name='ground_plane'>
      <static>1</static>
      <link name='link'>
        <collision name='collision'>
          <geometry>
            <plane>
              <normal>0 0 1</normal>
              <size>100 100</size>
            </plane>
          </geometry>
          <surface>
            <friction>
              <ode>
                <mu>100</mu>
                <mu2>50</mu2>
              </ode>
              <torsional>
                <ode/>
              </torsional>
            </friction>
            <contact>
              <ode/>
            </contact>
            <bounce/>
          </surface>
          <max_contacts>10</max_contacts>
        </collision>
        <visual name='visual'>
          <cast_shadows>0</cast_shadows>
          <geometry>
            <plane>
              <normal>0 0 1</normal>
              <size>100 100</size>
            </plane>
          </geometry>
          <material>
            <script>
              <uri>file://media/materials/scripts/gazebo.material</uri>
              <name>Gazebo/Grey</name>
            </script>
          </material>
        </visual>
        <self_collide>0</self_collide>
        <kinematic>0</kinematic>
        <gravity>1</gravity>
      </link>
    </model>
    <model name='brsu_ground_floor'>
      <pose frame=''>-85 -30 0 0 -0 0</pose>
      <static>1</static>
      <link name='body'>
        <visual name='visual'>
          <geometry>
            <mesh>
              <uri>file://brsu_ground_floor.stl</uri>
              <scale>1 1 1</scale>
            </mesh>
          </geometry>
        </visual>
        <collision name='collision'>
          <geometry>
            <mesh>
              <uri>file://brsu_ground_floor.stl</uri>
              <scale>1 1 1</scale>
            </mesh>
          </geometry>
          <max_contacts>10</max_contacts>
          <surface>
            <contact>
              <ode/>
            </contact>
            <bounce/>
            <friction>
              <torsional>
                <ode/>
              </torsional>
              <ode/>
            </friction>
          </surface>
        </collision>
        <self_collide>0</self_collide>
        <kinematic>0</kinematic>
        <gravity>1</gravity>
      </link>
    </model>
    <model name='navigation_sign_right'>
      <pose frame=''>0 0 0.15 0 -0 0</pose>
      <link name='navigation_sign_right'>
        <visual name='visual'>
          <geometry>
            <box>
              <size>0.3 0.03 0.3</size>
            </box>
          </geometry>
          <material>
            <script>
              <uri>model://navigation_sign_right/materials/scripts</uri>
              <uri>model://navigation_sign_right/materials/textures</uri>
              <name>NavigationSign/Right</name>
            </script>
            <ambient>1 1 1 1</ambient>
            <diffuse>1 1 1 1</diffuse>
            <specular>0 0 0 1</specular>
            <emissive>1 1 1 0</emissive>
            <shader type='vertex'>
              <normal_map>__default__</normal_map>
            </shader>
          </material>
          <cast_shadows>1</cast_shadows>
          <transparency>0</transparency>
        </visual>
        <collision name='collision'>
          <laser_retro>0</laser_retro>
          <max_contacts>10</max_contacts>
          <geometry>
            <box>
              <size>0.3 0.03 0.3</size>
            </box>
          </geometry>
          <surface>
            <contact>
              <ode/>
            </contact>
            <bounce/>
            <friction>
              <torsional>
                <ode/>
              </torsional>
              <ode/>
            </friction>
          </surface>
        </collision>
        <self_collide>0</self_collide>
        <kinematic>0</kinematic>
        <gravity>1</gravity>
      </link>
      <static>1</static>
      <allow_auto_disable>1</allow_auto_disable>
    </model>
    <model name='navigation_sign_left'>
      <pose frame=''>0 0 0.15 0 -0 0</pose>
      <link name='navigation_sign_left'>
        <visual name='visual'>
          <geometry>
            <box>
              <size>0.3 0.03 0.3</size>
            </box>
          </geometry>
          <material>
            <script>
              <uri>model://navigation_sign_left/materials/scripts</uri>
              <uri>model://navigation_sign_left/materials/textures</uri>
              <name>NavigationSign/Left</name>
            </script>
            <ambient>1 1 1 1</ambient>
            <diffuse>1 1 1 1</diffuse>
            <specular>0 0 0 1</specular>
            <emissive>1 1 1 0</emissive>
            <shader type='vertex'>
              <normal_map>__default__</normal_map>
            </shader>
          </material>
          <cast_shadows>1</cast_shadows>
          <transparency>0</transparency>
        </visual>
        <collision name='collision'>
          <laser_retro>0</laser_retro>
          <max_contacts>10</max_contacts>
          <geometry>
            <box>
              <size>0.3 0.03 0.3</size>
            </box>
          </geometry>
          <surface>
            <contact>
              <ode/>
            </contact>
            <bounce/>
            <friction>
              <torsional>
                <ode/>
              </torsional>
              <ode/>
            </friction>
          </surface>
        </collision>
        <self_collide>0</self_collide>
        <kinematic>0</kinematic>
        <gravity>1</gravity>
      </link>
      <static>1</static>
      <allow_auto_disable>1</allow_auto_disable>
    </model>
    <gravity>0 0 -9.8</gravity>
    <magnetic_field>6e-06 2.3e-05 -4.2e-05</magnetic_field>
    <atmosphere type='adiabatic'/>
    <physics name='default_physics' default='0' type='ode'>
      <max_step_size>0.001</max_step_size>
      <real_time_factor>1</real_time_factor>
      <real_time_update_rate>1000</real_time_update_rate>
    </physics>
    <scene>
      <ambient>0.4 0.4 0.4 1</ambient>
      <background>0.7 0.7 0.7 1</background>
      <shadows>1</shadows>
    </scene>
    <spherical_coordinates>
      <surface_model>EARTH_WGS84</surface_model>
      <latitude_deg>0</latitude_deg>
      <longitude_deg>0</longitude_deg>
      <elevation>0</elevation>
      <heading_deg>0</heading_deg>
    </spherical_coordinates>
    <model name='ropod'>
      <link name='ropod/base_link'>
        <pose frame=''>0 0 0 0 -0 0</pose>
        <inertial>
          <pose frame=''>1e-06 0 0 0 -0 0</pose>
          <mass>8.00003</mass>
          <inertia>
            <ixx>0.500003</ixx>
            <ixy>0</ixy>
            <ixz>-2.99999e-07</ixz>
            <iyy>0.500005</iyy>
            <iyz>0</iyz>
            <izz>0.500005</izz>
          </inertia>
        </inertial>
        <collision name='ropod/base_link_collision'>
          <pose frame=''>0 0 0 0 -0 0</pose>
          <geometry>
            <box>
              <size>0.5 0.5 0.2</size>
            </box>
          </geometry>
          <surface>
            <contact>
              <ode/>
            </contact>
            <friction>
              <ode/>
              <torsional>
                <ode/>
              </torsional>
            </friction>
            <bounce/>
          </surface>
          <max_contacts>10</max_contacts>
        </collision>
        <collision name='ropod/base_link_fixed_joint_lump__ropod/camera_collision_1'>
          <pose frame=''>0.3 0 0 0 -0 0</pose>
          <geometry>
            <box>
              <size>0.025 0.025 0.025</size>
            </box>
          </geometry>
          <surface>
            <contact>
              <ode/>
            </contact>
            <friction>
              <ode/>
              <torsional>
                <ode/>
              </torsional>
            </friction>
            <bounce/>
          </surface>
          <max_contacts>10</max_contacts>
        </collision>
        <collision name='ropod/base_link_fixed_joint_lump__ropod/laser/scan_collision_2'>
          <pose frame=''>0.3 0 0.1 0 -0 0</pose>
          <geometry>
            <box>
              <size>0.1 0.1 0.1</size>
            </box>
          </geometry>
          <surface>
            <contact>
              <ode/>
            </contact>
            <friction>
              <ode/>
              <torsional>
                <ode/>
              </torsional>
            </friction>
            <bounce/>
          </surface>
          <max_contacts>10</max_contacts>
        </collision>
        <collision name='ropod/base_link_fixed_joint_lump__ropod/imu_collision_3'>
          <pose frame=''>0 0 0 0 -0 0</pose>
          <geometry>
            <box>
              <size>0.025 0.025 0.025</size>
            </box>
          </geometry>
          <max_contacts>10</max_contacts>
          <surface>
            <contact>
              <ode/>
            </contact>
            <bounce/>
            <friction>
              <torsional>
                <ode/>
              </torsional>
              <ode/>
            </friction>
          </surface>
        </collision>
        <visual name='ropod/base_link_visual'>
          <pose frame=''>0 0 0 0 -0 0</pose>
          <geometry>
            <box>
              <size>0.5 0.5 0.2</size>
            </box>
          </geometry>
          <material>
            <script>
              <name>Gazebo/RustySteel</name>
              <uri>file://media/materials/scripts/gazebo.material</uri>
            </script>
          </material>
        </visual>
        <visual name='ropod/base_link_fixed_joint_lump__ropod/camera_visual_1'>
          <pose frame=''>0.3 0 0 0 -0 0</pose>
          <geometry>
            <box>
              <size>0.025 0.025 0.025</size>
            </box>
          </geometry>
          <material>
            <script>
              <uri>__default__</uri>
              <name>__default__</name>
            </script>
          </material>
        </visual>
        <visual name='ropod/base_link_fixed_joint_lump__ropod/laser/scan_visual_2'>
          <pose frame=''>0.3 0 0.1 0 -0 0</pose>
          <geometry>
            <mesh>
              <scale>1 1 1</scale>
              <uri>/media/psf/Home/mystuff/MAS/thesis/codes/thesis_ws/src/ropod/ropod_description/meshes/hokuyo.dae</uri>
            </mesh>
          </geometry>
          <material>
            <script>
              <uri>__default__</uri>
              <name>__default__</name>
            </script>
          </material>
        </visual>
        <visual name='ropod/base_link_fixed_joint_lump__ropod/imu_visual_3'>
          <pose frame=''>0 0 0 0 -0 0</pose>
          <geometry>
            <box>
              <size>0.025 0.025 0.025</size>
            </box>
          </geometry>
        </visual>
        <velocity_decay/>
        <velocity_decay/>
        <sensor name='front_camera' type='camera'>
          <update_rate>30</update_rate>
          <camera name='head'>
            <horizontal_fov>1.39626</horizontal_fov>
            <image>
              <width>800</width>
              <height>600</height>
              <format>R8G8B8</format>
            </image>
            <clip>
              <near>0.02</near>
              <far>300</far>
            </clip>
            <noise>
              <type>gaussian</type>
              <mean>0</mean>
              <stddev>0.007</stddev>
            </noise>
          </camera>
          <plugin name='camera_controller' filename='libgazebo_ros_camera.so'>
            <alwaysOn>true</alwaysOn>
            <updateRate>0.0</updateRate>
            <cameraName>/ropod/camera</cameraName>
            <imageTopicName>image_raw</imageTopicName>
            <cameraInfoTopicName>camera_info</cameraInfoTopicName>
            <frameName>ropod/camera</frameName>
            <hackBaseline>0.07</hackBaseline>
            <distortionK1>0.0</distortionK1>
            <distortionK2>0.0</distortionK2>
            <distortionK3>0.0</distortionK3>
            <distortionT1>0.0</distortionT1>
            <distortionT2>0.0</distortionT2>
            <robotNamespace>/</robotNamespace>
          </plugin>
          <pose frame=''>0.3 0 0 0 -0 0</pose>
        </sensor>
        <gravity>1</gravity>
        <velocity_decay/>
        <self_collide>0</self_collide>
        <sensor name='hokuyo_sensor' type='ray'>
          <visualize>1</visualize>
          <update_rate>20</update_rate>
          <ray>
            <scan>
              <horizontal>
                <samples>360</samples>
                <resolution>1</resolution>
                <min_angle>-1.57</min_angle>
                <max_angle>1.57</max_angle>
              </horizontal>
              <vertical>
                <samples>1</samples>
                <min_angle>0</min_angle>
                <max_angle>0</max_angle>
              </vertical>
            </scan>
            <range>
              <min>0.1</min>
              <max>5</max>
              <resolution>0.1</resolution>
            </range>
            <noise>
              <type>gaussian</type>
              <mean>0</mean>
              <stddev>0.01</stddev>
            </noise>
          </ray>
          <plugin name='gazebo_ros_head_hokuyo_controller' filename='libgazebo_ros_laser.so'>
            <robotNamespace>/</robotNamespace>
            <topicName>/ropod/laser/scan</topicName>
            <frameName>ropod/laser/scan</frameName>
          </plugin>
          <pose frame=''>0.3 0 0.1 0 -0 0</pose>
        </sensor>
        <kinematic>0</kinematic>
      </link>
      <link name='left_back_wheel'>
        <pose frame=''>-0.2 0.2 -0.1 -1.57 0 0</pose>
        <inertial>
          <pose frame=''>0 0 0 0 -0 0</pose>
          <mass>1</mass>
          <inertia>
            <ixx>0.001</ixx>
            <ixy>0</ixy>
            <ixz>0</ixz>
            <iyy>0.001</iyy>
            <iyz>0</iyz>
            <izz>0.001</izz>
          </inertia>
        </inertial>
        <collision name='left_back_wheel_collision'>
          <pose frame=''>0 0 0 0 -0 0</pose>
          <geometry>
            <cylinder>
              <length>0.04</length>
              <radius>0.08</radius>
            </cylinder>
          </geometry>
          <surface>
            <contact>
              <ode/>
            </contact>
            <friction>
              <ode/>
              <torsional>
                <ode/>
              </torsional>
            </friction>
            <bounce/>
          </surface>
          <max_contacts>10</max_contacts>
        </collision>
        <visual name='left_back_wheel_visual'>
          <pose frame=''>0 0 0 0 -0 0</pose>
          <geometry>
            <cylinder>
              <length>0.04</length>
              <radius>0.08</radius>
            </cylinder>
          </geometry>
          <material>
            <script>
              <name>Gazebo/Black</name>
              <uri>file://media/materials/scripts/gazebo.material</uri>
            </script>
          </material>
        </visual>
        <gravity>1</gravity>
        <velocity_decay/>
        <self_collide>0</self_collide>
        <kinematic>0</kinematic>
      </link>
      <joint name='left_back_wheel_joint' type='revolute'>
        <child>left_back_wheel</child>
        <parent>ropod/base_link</parent>
        <axis>
          <xyz>0 1 0.000796</xyz>
          <limit>
            <lower>-1e+16</lower>
            <upper>1e+16</upper>
          </limit>
          <dynamics>
            <spring_reference>0</spring_reference>
            <spring_stiffness>0</spring_stiffness>
          </dynamics>
          <use_parent_model_frame>1</use_parent_model_frame>
        </axis>
      </joint>
      <link name='left_front_wheel'>
        <pose frame=''>0.2 0.2 -0.1 -1.57 0 0</pose>
        <inertial>
          <pose frame=''>0 0 0 0 -0 0</pose>
          <mass>1</mass>
          <inertia>
            <ixx>0.001</ixx>
            <ixy>0</ixy>
            <ixz>0</ixz>
            <iyy>0.001</iyy>
            <iyz>0</iyz>
            <izz>0.001</izz>
          </inertia>
        </inertial>
        <collision name='left_front_wheel_collision'>
          <pose frame=''>0 0 0 0 -0 0</pose>
          <geometry>
            <cylinder>
              <length>0.04</length>
              <radius>0.08</radius>
            </cylinder>
          </geometry>
          <surface>
            <contact>
              <ode/>
            </contact>
            <friction>
              <ode/>
              <torsional>
                <ode/>
              </torsional>
            </friction>
            <bounce/>
          </surface>
          <max_contacts>10</max_contacts>
        </collision>
        <visual name='left_front_wheel_visual'>
          <pose frame=''>0 0 0 0 -0 0</pose>
          <geometry>
            <cylinder>
              <length>0.04</length>
              <radius>0.08</radius>
            </cylinder>
          </geometry>
          <material>
            <script>
              <name>Gazebo/Black</name>
              <uri>file://media/materials/scripts/gazebo.material</uri>
            </script>
          </material>
        </visual>
        <gravity>1</gravity>
        <velocity_decay/>
        <self_collide>0</self_collide>
        <kinematic>0</kinematic>
      </link>
      <joint name='left_front_wheel_joint' type='revolute'>
        <child>left_front_wheel</child>
        <parent>ropod/base_link</parent>
        <axis>
          <xyz>0 1 0.000796</xyz>
          <limit>
            <lower>-1e+16</lower>
            <upper>1e+16</upper>
          </limit>
          <dynamics>
            <spring_reference>0</spring_reference>
            <spring_stiffness>0</spring_stiffness>
          </dynamics>
          <use_parent_model_frame>1</use_parent_model_frame>
        </axis>
      </joint>
      <link name='right_back_wheel'>
        <pose frame=''>-0.2 -0.2 -0.1 -1.57 0 0</pose>
        <inertial>
          <pose frame=''>0 0 0 0 -0 0</pose>
          <mass>1</mass>
          <inertia>
            <ixx>0.001</ixx>
            <ixy>0</ixy>
            <ixz>0</ixz>
            <iyy>0.001</iyy>
            <iyz>0</iyz>
            <izz>0.001</izz>
          </inertia>
        </inertial>
        <collision name='right_back_wheel_collision'>
          <pose frame=''>0 0 0 0 -0 0</pose>
          <geometry>
            <cylinder>
              <length>0.04</length>
              <radius>0.08</radius>
            </cylinder>
          </geometry>
          <surface>
            <contact>
              <ode/>
            </contact>
            <friction>
              <ode/>
              <torsional>
                <ode/>
              </torsional>
            </friction>
            <bounce/>
          </surface>
          <max_contacts>10</max_contacts>
        </collision>
        <visual name='right_back_wheel_visual'>
          <pose frame=''>0 0 0 0 -0 0</pose>
          <geometry>
            <cylinder>
              <length>0.04</length>
              <radius>0.08</radius>
            </cylinder>
          </geometry>
          <material>
            <script>
              <name>Gazebo/Black</name>
              <uri>file://media/materials/scripts/gazebo.material</uri>
            </script>
          </material>
        </visual>
        <gravity>1</gravity>
        <velocity_decay/>
        <self_collide>0</self_collide>
        <kinematic>0</kinematic>
      </link>
      <joint name='right_back_wheel_joint' type='revolute'>
        <child>right_back_wheel</child>
        <parent>ropod/base_link</parent>
        <axis>
          <xyz>0 1 0.000796</xyz>
          <limit>
            <lower>-1e+16</lower>
            <upper>1e+16</upper>
          </limit>
          <dynamics>
            <spring_reference>0</spring_reference>
            <spring_stiffness>0</spring_stiffness>
          </dynamics>
          <use_parent_model_frame>1</use_parent_model_frame>
        </axis>
      </joint>
      <link name='right_front_wheel'>
        <pose frame=''>0.2 -0.2 -0.1 -1.57 0 0</pose>
        <inertial>
          <pose frame=''>0 0 0 0 -0 0</pose>
          <mass>1</mass>
          <inertia>
            <ixx>0.001</ixx>
            <ixy>0</ixy>
            <ixz>0</ixz>
            <iyy>0.001</iyy>
            <iyz>0</iyz>
            <izz>0.001</izz>
          </inertia>
        </inertial>
        <collision name='right_front_wheel_collision'>
          <pose frame=''>0 0 0 0 -0 0</pose>
          <geometry>
            <cylinder>
              <length>0.04</length>
              <radius>0.08</radius>
            </cylinder>
          </geometry>
          <surface>
            <contact>
              <ode/>
            </contact>
            <friction>
              <ode/>
              <torsional>
                <ode/>
              </torsional>
            </friction>
            <bounce/>
          </surface>
          <max_contacts>10</max_contacts>
        </collision>
        <visual name='right_front_wheel_visual'>
          <pose frame=''>0 0 0 0 -0 0</pose>
          <geometry>
            <cylinder>
              <length>0.04</length>
              <radius>0.08</radius>
            </cylinder>
          </geometry>
          <material>
            <script>
              <name>Gazebo/Black</name>
              <uri>file://media/materials/scripts/gazebo.material</uri>
            </script>
          </material>
        </visual>
        <gravity>1</gravity>
        <velocity_decay/>
        <self_collide>0</self_collide>
        <kinematic>0</kinematic>
      </link>
      <joint name='right_front_wheel_joint' type='revolute'>
        <child>right_front_wheel</child>
        <parent>ropod/base_link</parent>
        <axis>
          <xyz>0 1 0.000796</xyz>
          <limit>
            <lower>-1e+16</lower>
            <upper>1e+16</upper>
          </limit>
          <dynamics>
            <spring_reference>0</spring_reference>
            <spring_stiffness>0</spring_stiffness>
          </dynamics>
          <use_parent_model_frame>1</use_parent_model_frame>
        </axis>
      </joint>
      <plugin name='imu_controller' filename='libgazebo_ros_imu.so'>
        <alwaysOn>true</alwaysOn>
        <updateRate>50.0</updateRate>
        <robotNamespace>ropod</robotNamespace>
        <topicName>ropod/imu</topicName>
        <gaussianNoise>0.0001</gaussianNoise>
        <xyzOffsets>0 0 0</xyzOffsets>
        <rpyOffsets>0 0 0</rpyOffsets>
        <position name='imu_position'/>
        <bodyName>ropod/base_link</bodyName>
        <xyzOffset>0 0 0</xyzOffset>
        <rpyOffset>0 -0 0</rpyOffset>
      </plugin>
      <plugin name='magnetometer' filename='libhector_gazebo_ros_magnetic.so'>
        <updateRate>20.0</updateRate>
        <bodyname>ropod/imu</bodyname>
        <topicName>ropod/magnetometer</topicName>
        <referenceHeading>0.0</referenceHeading>
        <declination>3.0333</declination>
        <inclination>60.0</inclination>
        <offset>0 0 0</offset>
        <driftFrequency>0 0 0</driftFrequency>
        <gaussianNoise>0 0 0</gaussianNoise>
        <robotNamespace>/</robotNamespace>
      </plugin>
      <static>0</static>
      <plugin name='skid_steer_drive_controller' filename='libgazebo_ros_skid_steer_drive.so'>
        <updateRate>50.0</updateRate>
        <robotNamespace>ropod</robotNamespace>
        <leftFrontJoint>left_front_wheel_joint</leftFrontJoint>
        <rightFrontJoint>right_front_wheel_joint</rightFrontJoint>
        <leftRearJoint>left_back_wheel_joint</leftRearJoint>
        <rightRearJoint>right_back_wheel_joint</rightRearJoint>
        <wheelSeparation>0.2</wheelSeparation>
        <wheelDiameter>0.035</wheelDiameter>
        <robotBaseFrame>ropod/base_link</robotBaseFrame>
        <torque>5</torque>
        <commandTopic>cmd_vel</commandTopic>
        <odometryTopic>odom</odometryTopic>
        <odometryFrame>ropod/odom</odometryFrame>
        <childFrame>ropod/base_link</childFrame>
        <broadcastTF>true</broadcastTF>
        <gaussianNoise>0.005</gaussianNoise>
      </plugin>
      <pose frame=''>0 0 1 0 -0 0</pose>
    </model>
    <state world_name='default'>
      <sim_time>360 499000000</sim_time>
      <real_time>442 139749258</real_time>
      <wall_time>1552832450 156416096</wall_time>
      <iterations>360499</iterations>
      <model name='brsu_ground_floor'>
        <pose frame=''>-85 -30 0 0 -0 0</pose>
        <scale>1 1 1</scale>
        <link name='body'>
          <pose frame=''>-85 -30 0 0 -0 0</pose>
          <velocity>0 0 0 0 -0 0</velocity>
          <acceleration>0 0 0 0 -0 0</acceleration>
          <wrench>0 0 0 0 -0 0</wrench>
        </link>
      </model>
      <model name='ground_plane'>
        <pose frame=''>0 0 0 0 -0 0</pose>
        <scale>1 1 1</scale>
        <link name='link'>
          <pose frame=''>0 0 0 0 -0 0</pose>
          <velocity>0 0 0 0 -0 0</velocity>
          <acceleration>0 0 0 0 -0 0</acceleration>
          <wrench>0 0 0 0 -0 0</wrench>
        </link>
      </model>
      <model name='navigation_sign_left'>
        <pose frame=''>2.00761 3.3957 0.15 0 -0 0</pose>
        <scale>1 1 1</scale>
        <link name='navigation_sign_left'>
          <pose frame=''>2.00761 3.3957 0.15 0 -0 0</pose>
          <velocity>0 0 0 0 -0 0</velocity>
          <acceleration>0 0 0 0 -0 0</acceleration>
          <wrench>0 0 0 0 -0 0</wrench>
        </link>
      </model>
      <model name='navigation_sign_right'>
        <pose frame=''>-1.7024 2.87283 0.15 0 -0 1.55671</pose>
        <scale>1 1 1</scale>
        <link name='navigation_sign_right'>
          <pose frame=''>-1.7024 2.87283 0.15 0 -0 1.55671</pose>
          <velocity>0 0 0 0 -0 0</velocity>
          <acceleration>0 0 0 0 -0 0</acceleration>
          <wrench>0 0 0 0 -0 0</wrench>
        </link>
      </model>
      <model name='ropod'>
        <pose frame=''>0.922248 -0.072037 0.180015 -1e-06 -0 1.46299</pose>
        <scale>1 1 1</scale>
        <link name='left_back_wheel'>
          <pose frame=''>0.70189 -0.249357 0.080015 -1.5699 -0.534837 1.46254</pose>
          <velocity>-0.000519 -0.000103 0.002701 0.000483 -0.006336 0.002645</velocity>
          <acceleration>0.398804 -0.362735 5.57062 -2.53152 -0.541912 2.37533</acceleration>
          <wrench>0.398804 -0.362735 5.57062 0 -0 0</wrench>
        </link>
        <link name='left_front_wheel'>
          <pose frame=''>0.744929 0.148321 0.080015 -1.56919 1.07519 1.4644</pose>
          <velocity>-0.000772 -0.000151 -0.000464 -0.007566 0.002178 0.001271</velocity>
          <acceleration>0.27571 -0.47626 -0.7294 1.64948 -1.40949 -0.054433</acceleration>
          <wrench>0.27571 -0.47626 -0.7294 0 -0 0</wrench>
        </link>
        <link name='right_back_wheel'>
          <pose frame=''>1.09957 -0.292395 0.080015 -1.57002 -0.146657 1.46288</pose>
          <velocity>-0.000498 3.6e-05 0.005392 -0.001155 -0.006058 0.002373</velocity>
          <acceleration>0.415121 -0.329948 10.955 2.12973 -0.107495 1.92452</acceleration>
          <wrench>0.415121 -0.329948 10.955 0 -0 0</wrench>
        </link>
        <link name='right_front_wheel'>
          <pose frame=''>1.14261 0.105283 0.080015 -1.57003 -0.147701 1.46288</pose>
          <velocity>-0.000633 4.6e-05 0.002287 -0.001275 -0.007706 0.002381</velocity>
          <acceleration>0.385605 -0.332418 4.74193 -1.27901 -0.025136 -1.21425</acceleration>
          <wrench>0.385605 -0.332418 4.74193 0 -0 0</wrench>
        </link>
        <link name='ropod/base_link'>
          <pose frame=''>0.922248 -0.072037 0.180015 -1e-06 -0 1.46299</pose>
          <velocity>-0.001183 0.000715 0.002476 -0.008459 -0.005925 0.000395</velocity>
          <acceleration>-0.907109 1.26494 5.13279 1.85534 0.636966 0.152463</acceleration>
          <wrench>-7.2569 10.1195 41.0625 0 -0 0</wrench>
        </link>
      </model>
      <light name='sun'>
        <pose frame=''>0 0 10 0 -0 0</pose>
      </light>
    </state>
    <gui fullscreen='0'>
      <camera name='user_camera'>
        <pose frame=''>0.451177 -5.30219 5.27253 0 0.747643 1.4122</pose>
        <view_controller>orbit</view_controller>
        <projection_type>perspective</projection_type>
      </camera>
    </gui>
  </world>
</sdf>
